<?xml version="1.0"?>
<robot xmlns:xacro="http://www.ros.org/wiki/xacro" name="differential_robot">
  <xacro:property name="wheelmass" value="0.015" />
  <xacro:property name="wheelradius" value="0.036" />
  <xacro:property name="basewidth" value="0.350" />

  <material name="blue">
    <color rgba="0 0 0.8 1"/>
  </material>
  <material name="black">
    <color rgba="0 0 0 1"/>
  </material>
  <material name="white">
    <color rgba="1 1 1 1"/>
  </material>

  <link name="base_footprint"/>

  <link name="base_link">
    <visual>
      <origin xyz="0 0 0" rpy="0 0 0" />
      <geometry>
        <cylinder length="0.03" radius="${basewidth/2}"/>
      </geometry>
    </visual>
    <collision>
      <geometry>
        <cylinder length="0.03" radius="${basewidth/2}"/>
      </geometry>
    </collision>
    <inertial>
      <mass value="0.100"/>
      <inertia ixx="0.000773125" ixy="0.0" ixz="0.0" iyy="0.000773125" iyz="0.0" izz="0.00153125"/>
    </inertial>
  </link>

  <joint name="footprint_to_base" type="fixed">
    <parent link="base_footprint"/>
    <child link="base_link"/>
    <origin xyz="0 0 0.036"/>
  </joint>  

  <link name="left_wheel">
    <visual>
      <geometry>
        <cylinder length="0.03" radius="${wheelradius}"/>
      </geometry>
      <origin rpy="0 0 0" xyz="0 0 0"/>
      <material name="black"/>
    </visual>
    <collision>
      <geometry>
        <cylinder length="0.03" radius="${wheelradius}"/>
      </geometry>
    </collision>
    <inertial>
      <mass value="${wheelmass}"/>
      <inertia ixx="5.985e-6" ixy="0.0" ixz="0.0" iyy="5.985e-6" iyz="0.0" izz="9.72e-6"/>
    </inertial>
  </link>

  <joint name="base_to_left_wheel" type="continuous">
    <axis xyz="0 0 1"/>
    <parent link="base_link"/>
    <child link="left_wheel"/>
    <origin rpy="-1.57075 0 0" xyz="0 ${basewidth/2} 0"/>
  </joint>

  <link name="left_wheel_marker">
    <visual>
      <geometry>
        <box size="0.03 0.001 0.01"/>
      </geometry>
      <origin rpy="0 0 0" xyz="0 0 0"/>
      <material name="white"/>
    </visual>
  </link>

  <joint name="left_wheel_to_marker" type="fixed">
    <parent link="left_wheel"/>
    <child link="left_wheel_marker"/>
    <origin rpy="-1.57075 0 0" xyz="0 0 0.0155"/>
  </joint>

  <link name="right_wheel">
    <visual>
      <geometry>
        <cylinder length="0.030" radius="${wheelradius}"/>
      </geometry>
      <origin rpy="0 0 0" xyz="0 0 0"/>
      <material name="black"/>
    </visual>
    <collision>
      <geometry>
        <cylinder length="0.03" radius="${wheelradius}"/>
      </geometry>
    </collision>
    <inertial>
      <mass value="${wheelmass}"/>
      <inertia ixx="5.985e-6" ixy="0.0" ixz="0.0" iyy="5.985e-6" iyz="0.0" izz="9.72e-6"/>
    </inertial>
  </link>

  <joint name="base_to_right_wheel" type="continuous">
    <axis xyz="0 0 -1"/>
    <parent link="base_link"/>
    <child link="right_wheel"/>
    <origin rpy="1.57075 0 0" xyz="0 ${-basewidth/2} 0"/>
  </joint>

  <link name="right_wheel_marker">
    <visual>
      <geometry>
        <box size="0.03 0.001 0.01"/>
      </geometry>
      <origin rpy="0 0 0" xyz="0 0 0"/>
      <material name="white"/>
    </visual>
  </link>

  <joint name="right_wheel_to_marker" type="fixed">
    <parent link="right_wheel"/>
    <child link="right_wheel_marker"/>
    <origin rpy="1.57075 0 0" xyz="0 0 0.0155"/>
  </joint>

  <link name="head">
    <visual>
      <geometry>
        <box size="0.030 0.030 0.030"/>
      </geometry>
      <origin rpy="0 0 0" xyz="0 0 0"/>
      <material name="blue"/>
    </visual>
    <collision>
      <geometry>
        <box size="0.03 0.03 0.03"/>
      </geometry>
    </collision>
    <inertial>
      <mass value="0.02"/>
      <inertia ixx="3e-6" ixy="0.0" ixz="0.0" iyy="3e-6" iyz="0.0" izz="3e-6"/>
    </inertial>
  </link>
  
  <joint name="base_to_head" type="fixed">
    <parent link="base_link"/>
    <child link="head"/>
    <origin xyz="0.125 0 0.030"/>
  </joint>
  
  <link name="passive_wheel_holder">
    <visual>
      <geometry>
        <cylinder length="0.016" radius="0.005"/>
      </geometry>
      <origin rpy="0 0 0" xyz="0 0 0"/>
      <material name="white"/>
    </visual>
    <collision>
      <geometry>
        <cylinder length="0.016" radius="0.005"/>
      </geometry>
    </collision>
    <inertial>
      <mass value="0.02"/>
      <inertia ixx="5.51666667e-7" ixy="0.0" ixz="0.0" iyy="5.51666667e-7" iyz="0.0" izz="2.5e-7"/>
    </inertial>
  </link>
  
  <joint name="base_to_holder" type="fixed">
    <parent link="base_link"/>
    <child link="passive_wheel_holder"/>
    <origin xyz="0.125 0 -0.023"/>
  </joint>
  
  <link name="passive_wheel">
    <visual>
      <geometry>
        <sphere radius="0.005"/>
      </geometry>
      <origin rpy="0 0 0" xyz="0 0 0"/>
      <material name="white"/>
    </visual>
    <collision>
      <geometry>
        <sphere radius="0.005"/>
      </geometry>
    </collision>
    <inertial>
      <mass value="0.02"/>
      <inertia ixx="2e-7" ixy="0.0" ixz="0.0" iyy="2e-7" iyz="0.0" izz="2e-7"/>
    </inertial>
  </link>
  
  <joint name="holder_to_wheel" type="fixed">
    <parent link="passive_wheel_holder"/>
    <child link="passive_wheel"/>
    <origin xyz="0 0 -0.008"/>
  </joint>   
</robot>
